Workbook
Name _100_PV: #REF!
Name _100_SVI: #REF!
Name _1000_XM: #REF!
Name _145110: #REF!
Name _162460: [4]STEPHAN!$B$2:$P$71
Name _170_LIGHT: #REF!
Name _170_PV: #REF!
Name _171015: #REF!
Name _171064: #REF!
Name _171066: #REF!
Name _171068: #REF!
Name _171510: #REF!
Name _171562: #REF!
Name _172012: #REF!
Name _172020: #REF!
Name _172022: #REF!
Name _172062: #REF!
Name _172510: [4]STEPHAN!$B$2:$Q$71
Name _172610: [4]STEPHAN!$B$2:$Q$71
Name _176072: #REF!
Name A_impresión_IM: #REF!
Name bd: #REF!
Name bof: "ComboBox1"
Name dd: #REF!
Name EssLatest: "JAN"
Name EssLatest_10: "JAN"
Name EssLatest_11: "JAN"
Name EssLatest_12: "JAN"
Name EssLatest_13: "JAN"
Name EssLatest_14: "JAN"
Name EssLatest_15: "JAN"
Name EssLatest_16: "JAN"
Name EssLatest_18: "JAN"
Name EssLatest_2: "JANN0"
Name EssLatest_20: "YTDMM01"
Name EssLatest_25: "YTDMM01"
Name EssLatest_26: "YTDMM01"
Name EssLatest_3: "JANN0"
Name EssLatest_38: "JAN"
Name EssLatest_39: "JAN"
Name EssLatest_4: "JANN0"
Name EssLatest_47: "JAN"
Name EssLatest_48: "JAN"
Name EssLatest_5: "JANN0"
Name EssLatest_6: "YTDMM01"
Name EssLatest_7: "YTDMM01"
Name EssLatest_8: "YTDMM01"
Name EssLatest_9: "JAN"
Name EssOptions_10: "A3000001100130001011001101020_01 00"
Name EssOptions_11: "A3000001100130001011001101020_01 00"
Name EssOptions_12: "A3000001100130001011001101020_01 00"
Name EssOptions_13: "A3000001100130001011001101020_01 00"
Name EssOptions_14: "A3000001100130001011001101020_01 00"
Name EssOptions_15: "A3000001100130001011001101020_01 00"
Name EssOptions_16: "A3000001100130001011001101020_01 00"
Name EssOptions_18: "A3000001100130001011001101020_01 00"
Name EssOptions_2: "A1100000010121000011001111120_01000"
Name EssOptions_20: "A3100000000110001011011111020_01000"
Name EssOptions_25: "A3100000000130000000011100020_01000"
Name EssOptions_26: "A3100000000110001011011111020_01000"

Sheet Datos de partida
A1: 1. Presupuesto | B1: Modelo
A2: Datos del producto
A3: EST a salida de sal (%) | B3: 0.55
A4: MG a saida de sal (%) | B4: 0.28
A5: Coste de la leche en fabrica
A6: Precio pagado al ganadero (euros/L) | B6: 0.362
A7: Coste transporte + otros recogida (euros/L) | B7: 0.021
A8: Total euros/L | B8: =SUM(B6:B7) -> 0.383
A9: Reparto precio MG leche | B9: 0.5
A10: Reparto precio MP leche (1 - MG) | B10: =1-B9 -> 0.5
A11: Valor MG leche en fábrica (euros/L) | B11: =B30*B18/1000 -> 0.1915
A12: Valor MP leche en fábrica (euros/L) | B12: =B31*B19/1000 -> 0.1915
A13: Datos de materia prima
A14: Composición leche
A15: Materia grasa (% m/m) | B15: 0.0376
A16: Proteinas totales (% m/m) | B16: 0.0326
A17: Factor MG/MP | B17: =B15/B16 -> 1.1533742
A18: Materia grasa (g/L) | B18: =B15*B24 -> 38.887209
A19: Proteinas totales (g/L) | B19: =B16*B24 -> 33.716037
A20: Lactosa | B20: 48
A21: Sales minerales y otros | B21: 9
A22: Agua | B22: =B24-SUM(B18:B21) -> 904.63103
A23: Temperatura a la que se hace la medida (⁰C) | B23: 20
A24: Densidad | B24: =-0.2307*10^(-2)*B23^2-0.2655*B23+1040.51-B15*(-0.478*10^(-4)*B23^2+0.969*10^(-2)*B23+0.967) -> 1034.2343
A25: Composición nata suero (g/L)
A26: Materia grasa (% m/m) | B26: 0.43
A27: MG | B27: =B26*B40*1000 -> 423.62953
A28: MP | B28: 5.91
A29: Precio materia (euros/kg)
A30: MG | B30: =B8/B18*B9*1000 -> 4.9244985
A31: MP | B31: =B8/B19*B10*1000 -> 5.6797897
A32: Datos estándar
A33: Receta en volumen (debe sumar 100%)
A34: Leche (%) | B34: 1
A35: Nata de suero de recuperación (%) | B35: =1-B34 -> 0
A36: Coeficientes de recuperación
A37: Coef de recuperación MG
A38: Coef de recuperación MP | B38: 0.9465
A39: Otros datos
A40: Densidad nata (kg/L) | B40: =(-0.2307*10^(-2)*B23^2-0.2655*B23+1040.51-B26*100*(-0.478*10^(-4)*B23^2+0.969*10^(-2)*B23+0.967))/1000 -> 0.98518496
...

Sheet Ejemplo
A1: 1. Presupuesto | B1: Modelo | D1: Ejemplo 1 Paso 1 | E1: Ejemplo 1 Paso 2 - MG/ES | F1: Ejemplo 1 Paso 3- Precio | H1: Ejemplo 3 Estandarización MG | I1: Ejemplo 3 Estandarización MG y precio
A2: Datos del producto
A3: EST a salida de sal (%) | B3: 0.55 | D3: 0.55 | E3: 0.55 | F3: 0.55 | H3: 0.55 | I3: 0.55
A4: MG a saida de sal (%) | B4: 0.28 | D4: 0.28 | E4: 0.268 | F4: 0.268 | H4: 0.28 | I4: 0.28
A5: Coste de la leche en fabrica
A6: Precio pagado al ganadero (euros/L) | B6: 0.362 | D6: 0.362 | E6: 0.362 | F6: 0.329 | H6: 0.362 | I6: 0.345
A7: Coste transporte + otros recogida (euros/L) | B7: 0.021 | D7: 0.021 | E7: 0.021 | F7: 0.021 | H7: 0.021 | I7: 0.021
A8: Total euros/L | B8: =SUM(B6:B7) -> 0.383 | D8: =SUM(D6:D7) -> 0.383 | E8: =SUM(E6:E7) -> 0.383 | F8: =SUM(F6:F7) -> 0.35 | H8: =SUM(H6:H7) -> 0.383 | I8: =SUM(I6:I7) -> 0.366
A10: Reparto precio MG leche | B10: 0.5 | D10: 0.5 | E10: 0.5 | F10: 0.5 | H10: 0.5 | I10: 0.5
A11: Reparto precio MP leche (1 - MG) | B11: =1-B10 -> 0.5 | D11: =1-D10 -> 0.5 | E11: =1-E10 -> 0.5 | F11: =1-F10 -> 0.5 | H11: =1-H10 -> 0.5 | I11: =1-I10 -> 0.5
A12: Valor MG leche en fábrica (euros/L) | B12: =B31*B19/1000 -> 0.1915 | D12: =D31*D19/1000 -> 0.1915 | E12: =E31*E19/1000 -> 0.1915 | F12: =F31*F19/1000 -> 0.175 | H12: =H31*H19/1000 -> 0.1915 | I12: =I31*I19/1000 -> 0.183
A13: Valor MP leche en fábrica (euros/L) | B13: =B32*B20/1000 -> 0.1915 | D13: =D32*D20/1000 -> 0.1915 | E13: =E32*E20/1000 -> 0.1915 | F13: =F32*F20/1000 -> 0.175 | H13: =H32*H20/1000 -> 0.1915 | I13: =I32*I20/1000 -> 0.183
A14: Datos de materia prima
A15: Composición leche
A16: Materia grasa (% m/m) | B16: 0.0376 | D16: 0.0336 | E16: 0.0336 | F16: 0.0336 | H16: 0.0359 | I16: 0.0359
A17: Proteinas totales (% m/m) | B17: 0.0326 | D17: 0.0311 | E17: 0.0311 | F17: 0.0311 | H17: 0.0311 | I17: 0.0311
A18: Factor MG/MP | B18: =B16/B17 -> 1.1533742 | D18: =D16/D17 -> 1.0803859 | E18: =E16/E17 -> 1.0803859 | F18: =F16/F17 -> 1.0803859 | H18: =H16/H17 -> 1.1543408 | I18: =I16/I17 -> 1.1543408
A19: Materia grasa (g/L) | B19: =B16*B25 -> 38.887209 | D19: =D16*D25 -> 34.750425 | E19: =E16*E25 -> 34.750425 | F19: =F16*F25 -> 34.750425 | H19: =H16*H25 -> 37.12908 | I19: =I16*I25 -> 37.12908
A20: Proteinas totales (g/L) | B20: =B17*B25 -> 33.716037 | D20: =D17*D25 -> 32.164828 | E20: =E17*E25 -> 32.164828 | F20: =F17*F25 -> 32.164828 | H20: =H17*H25 -> 32.164746 | I20: =I17*I25 -> 32.164746
A21: Lactosa | B21: 48 | D21: 48 | E21: 48 | F21: 48 | H21: 48 | I21: 48
A22: Sales minerales y otros | B22: 9 | D22: 9 | E22: 9 | F22: 9 | H22: 9 | I22: 9
A23: Agua | B23: =B25-SUM(B19:B22) -> 904.63103 | D23: =D25-SUM(D19:D22) -> 910.32359 | E23: =E25-SUM(E19:E22) -> 910.32359 | F23: =F25-SUM(F19:F22) -> 910.32359 | H23: =H25-SUM(H19:H22) -> 907.94239 | I23: =I25-SUM(I19:I22) -> 907.94239
A24: Temperatura a la que se hace la medida (⁰C) | B24: 20 | D24: 20 | E24: 20 | F24: 20 | H24: 20 | I24: 20
A25: Densidad | B25: =-0.2307*10^(-2)*B24^2-0.2655*B24+1040.51-B16*(-0.478*10^(-4)*B24^2+0.969*10^(-2)*B24+0.967) -> 1034.2343 | D25: =-0.2307*10^(-2)*D24^2-0.2655*D24+1040.51-D16*(-0.478*10^(-4)*D24^2+0.969*10^(-2)*D24+0.967) -> 1034.2388 | E25: =-0.2307*10^(-2)*E24^2-0.2655*E24+1040.51-E16*(-0.478*10^(-4)*E24^2+0.969*10^(-2)*E24+0.967) -> 1034.2388 | F25: =-0.2307*10^(-2)*F24^2-0.2655*F24+1040.51-F16*(-0.478*10^(-4)*F24^2+0.969*10^(-2)*F24+0.967) -> 1034.2388 | H25: =-0.2307*10^(-2)*H24^2-0.2655*H24+1040.51-H16*(-0.478*10^(-4)*H24^2+0.969*10^(-2)*H24+0.967) -> 1034.2362 | I25: =-0.2307*10^(-2)*I24^2-0.2655*I24+1040.51-I16*(-0.478*10^(-4)*I24^2+0.969*10^(-2)*I24+0.967) -> 1034.2362
A26: Composición nata suero (g/L)
A27: Materia grasa (% m/m) | B27: 0.43 | D27: 0.43 | E27: 0.4102 | F27: 0.4102 | H27: 0.4102 | I27: 0.4102
A28: MG | B28: =B27*B41*1000 -> 423.62953 | D28: =D27*D41*1000 -> 423.62953 | E28: =E27*E41*1000 -> 405.05014 | F28: =F27*F41*1000 -> 405.05014 | H28: =H27*H41*1000 -> 405.05014 | I28: =I27*I41*1000 -> 405.05014
A29: MP | B29: 5.91 | D29: 5.91 | E29: 1.67 | F29: 1.67 | H29: 1.67 | I29: 1.67
A30: Precio materia (euros/kg)
A31: MG | B31: =B8/B19*B10*1000 -> 4.9244985 | D31: =D8/D19*D10*1000 -> 5.510724 | E31: =E8/E19*E10*1000 -> 5.510724 | F31: =F8/F19*F10*1000 -> 5.0359096 | H31: =H8/H19*H10*1000 -> 5.1576823 | I31: =I8/I19*I10*1000 -> 4.9287513
A32: MP | B32: =B8/B20*B11*1000 -> 5.6797897 | D32: =D8/D20*D11*1000 -> 5.9537082 | E32: =E8/E20*E11*1000 -> 5.9537082 | F32: =F8/F20*F11*1000 -> 5.4407255 | H32: =H8/H20*H11*1000 -> 5.9537233 | I32: =I8/I20*I11*1000 -> 5.6894588
A33: Datos estándar
A34: Receta en volumen (debe sumar 100%)
A35: Leche (%) | B35: 1 | D35: 1 | E35: 1 | F35: 1 | H35: 1 | I35: 1
A36: Nata de suero de recuperación (%) | B36: =1-B35 -> 0 | D36: =1-D35 -> 0 | E36: =1-E35 -> 0 | F36: =1-F35 -> 0 | H36: =1-H35 -> 0 | I36: =1-I35 -> 0
A37: Coeficientes de recuperación
A38: Coef de recuperación MG
A39: Coef de recuperación MP | B39: 0.9465 | D39: 0.9465 | E39: 0.9465 | F39: 0.9465 | H39: 0.9465 | I39: 0.9465
A40: Otros datos
A41: Densidad nata (kg/L) | B41: =(-0.2307*10^(-2)*B24^2-0.2655*B24+1040.51-B27*100*(-0.478*10^(-4)*B24^2+0.969*10^(-2)*B24+0.967))/1000 -> 0.98518496 | D41: =(-0.2307*10^(-2)*D24^2-0.2655*D24+1040.51-D27*100*(-0.478*10^(-4)*D24^2+0.969*10^(-2)*D24+0.967))/1000 -> 0.98518496 | E41: =(-0.2307*10^(-2)*E24^2-0.2655*E24+1040.51-E27*100*(-0.478*10^(-4)*E24^2+0.969*10^(-2)*E24+0.967))/1000 -> 0.98744549 | F41: =(-0.2307*10^(-2)*F24^2-0.2655*F24+1040.51-F27*100*(-0.478*10^(-4)*F24^2+0.969*10^(-2)*F24+0.967))/1000 -> 0.98744549 | H41: =(-0.2307*10^(-2)*H24^2-0.2655*H24+1040.51-H27*100*(-0.478*10^(-4)*H24^2+0.969*10^(-2)*H24+0.967))/1000 -> 0.98744549 | I41: =(-0.2307*10^(-2)*I24^2-0.2655*I24+1040.51-I27*100*(-0.478*10^(-4)*I24^2+0.969*10^(-2)*I24+0.967))/1000 -> 0.98744549
...

Sheet Ejemplo coef G como ESM y no MP
A1: 1. Presupuesto | B1: Mezcla | C1: Vaca | D1: Oveja | E1: Light
A2: Datos del producto
A3: EST a salida de sal (%) | B3: 0.5495 | C3: 0.5563 | D3: 0.5635 | E3: 0.5047
A4: MG a saida de sal (%) | B4: 0.3028 | C4: 0.3005 | D4: 0.3093 | E4: 0.2022
A5: Coste de la leche en fabrica
A6: Precio pagado al ganadero (euros/L) | B6: 0.362 | C6: 0.362 | D6: 0.362 | E6: 0.362
A7: Coste transporte + otros recogida (euros/L) | B7: 0.021 | C7: 0.021 | D7: 0.021 | E7: 0.021
A8: Total euros/L | B8: =SUM(B6:B7) -> 0.383 | C8: =SUM(C6:C7) -> 0.383 | D8: =SUM(D6:D7) -> 0.383 | E8: =SUM(E6:E7) -> 0.383
A10: Reparto precio MG leche | B10: 0.5 | C10: 0.5 | D10: 0.5 | E10: 0.5
A11: Reparto precio MP leche (1 - MG) | B11: =1-B10 -> 0.5 | C11: =1-C10 -> 0.5 | D11: =1-D10 -> 0.5 | E11: =1-E10 -> 0.5
A12: Valor MG leche en fábrica (euros/L) | B12: =B38*B19/1000 -> 0.1915 | C12: =C38*C19/1000 -> 0.1915 | D12: =D38*D19/1000 -> 0.1915 | E12: =E38*E19/1000 -> 0.1915
A13: Valor MP leche en fábrica (euros/L) | B13: =B39*B20/1000 -> 0.1915 | C13: =C39*C20/1000 -> 0.1915 | D13: =D39*D20/1000 -> 0.1915 | E13: =E39*E20/1000 -> 0.1915
A14: Datos de materia prima
A15: Composición leche
A16: Materia grasa (% m/m) | B16: 0.0376 | C16: 0.0376 | D16: 0.0376 | E16: 0.0376
A17: Proteinas totales (% m/m) | B17: 0.0326 | C17: 0.0326 | D17: 0.0326 | E17: 0.0326
A18: Factor MG/MP | B18: =B16/B17 -> 1.1533742 | C18: =C16/C17 -> 1.1533742 | D18: =D16/D17 -> 1.1533742 | E18: =E16/E17 -> 1.1533742
A19: Materia grasa (g/L) | B19: =B16*B25 -> 38.887209 | C19: =C16*C25 -> 38.887209 | D19: =D16*D25 -> 38.887209 | E19: =E16*E25 -> 38.887209
A20: Proteinas totales (g/L) | B20: =B17*B25 -> 33.716037 | C20: =C17*C25 -> 33.716037 | D20: =D17*D25 -> 33.716037 | E20: =E17*E25 -> 33.716037
A21: Lactosa | B21: 48 | C21: 48 | D21: 48 | E21: 48
A22: Sales minerales y otros | B22: 9 | C22: 9 | D22: 9 | E22: 9
A23: Agua | B23: =B25-SUM(B19:B22) -> 904.63103 | C23: =C25-SUM(C19:C22) -> 904.63103 | D23: =D25-SUM(D19:D22) -> 904.63103 | E23: =E25-SUM(E19:E22) -> 904.63103
A24: Temperatura a la que se hace la medida (⁰C) | B24: 20 | C24: 20 | D24: 20 | E24: 20
A25: Densidad | B25: =-0.2307*10^(-2)*B24^2-0.2655*B24+1040.51-B16*(-0.478*10^(-4)*B24^2+0.969*10^(-2)*B24+0.967) -> 1034.2343 | C25: =-0.2307*10^(-2)*C24^2-0.2655*C24+1040.51-C16*(-0.478*10^(-4)*C24^2+0.969*10^(-2)*C24+0.967) -> 1034.2343 | D25: =-0.2307*10^(-2)*D24^2-0.2655*D24+1040.51-D16*(-0.478*10^(-4)*D24^2+0.969*10^(-2)*D24+0.967) -> 1034.2343 | E25: =-0.2307*10^(-2)*E24^2-0.2655*E24+1040.51-E16*(-0.478*10^(-4)*E24^2+0.969*10^(-2)*E24+0.967) -> 1034.2343
A26: Composición suero entero (g/L)
A27: EST | B27: 6.5 | C27: 6.5 | D27: 6.5 | E27: 6.5
A28: MG | B28: 4 | C28: 4 | D28: 4 | E28: 4
A29: MP | B29: 8 | C29: 8 | D29: 8 | E29: 8
A30: Lactosa | B30: 48 | C30: 48 | D30: 48 | E30: 48
A31: Sales minerales y otros
A32: Densidad | B32: 1.03 | C32: 1.03 | D32: 1.03 | E32: 1.03
A33: Composición nata suero (g/L)
A34: Materia grasa (% m/m) | B34: 0.43 | C34: 0.43 | D34: 0.43 | E34: 0.43
A35: MG | B35: =B34*B48*1000 -> 423.62953 | C35: =C34*C48*1000 -> 423.62953 | D35: =D34*D48*1000 -> 423.62953 | E35: =E34*E48*1000 -> 423.62953
A36: MP | B36: 5.91 | C36: 5.91 | D36: 5.91 | E36: 5.91
A37: Precio materia (euros/kg)
A38: MG | B38: =B8/B19*B10*1000 -> 4.9244985 | C38: =C8/C19*C10*1000 -> 4.9244985 | D38: =D8/D19*D10*1000 -> 4.9244985 | E38: =E8/E19*E10*1000 -> 4.9244985
A39: MP | B39: =B8/B20*B11*1000 -> 5.6797897 | C39: =C8/C20*C11*1000 -> 5.6797897 | D39: =D8/D20*D11*1000 -> 5.6797897 | E39: =E8/E20*E11*1000 -> 5.6797897
A40: Datos estándar
A41: Receta en volumen (debe sumar 100%)
...
