Workbook
Name _100_PV: #REF!
Name _100_SVI: #REF!
Name _1000_XM: #REF!
Name _145110: #REF!
Name _162460: [4]STEPHAN!$B$2:$P$71
Name _170_LIGHT: #REF!
Name _170_PV: #REF!
Name _171015: #REF!
Name _171064: #REF!
Name _171066: #REF!
Name _171068: #REF!
Name _171510: #REF!
Name _171562: #REF!
Name _172012: #REF!
Name _172020: #REF!
Name _172022: #REF!
Name _172062: #REF!
Name _172510: [4]STEPHAN!$B$2:$Q$71
Name _172610: [4]STEPHAN!$B$2:$Q$71
Name _176072: #REF!
Name A_impresión_IM: #REF!
Name bd: #REF!
Name bof: "ComboBox1"
Name dd: #REF!
Name EssLatest: "JAN"
Name EssLatest_10: "JAN"
Name EssLatest_11: "JAN"
Name EssLatest_12: "JAN"
Name EssLatest_13: "JAN"
Name EssLatest_14: "JAN"
Name EssLatest_15: "JAN"
Name EssLatest_16: "JAN"
Name EssLatest_18: "JAN"
Name EssLatest_2: "JANN0"
Name EssLatest_20: "YTDMM01"
Name EssLatest_25: "YTDMM01"
Name EssLatest_26: "YTDMM01"
Name EssLatest_3: "JANN0"
Name EssLatest_38: "JAN"
Name EssLatest_39: "JAN"
Name EssLatest_4: "JANN0"
Name EssLatest_47: "JAN"
Name EssLatest_48: "JAN"
Name EssLatest_5: "JANN0"
Name EssLatest_6: "YTDMM01"
Name EssLatest_7: "YTDMM01"
Name EssLatest_8: "YTDMM01"
Name EssLatest_9: "JAN"
Name EssOptions_10: "A3000001100130001011001101020_01 00"
Name EssOptions_11: "A3000001100130001011001101020_01 00"
Name EssOptions_12: "A3000001100130001011001101020_01 00"
Name EssOptions_13: "A3000001100130001011001101020_01 00"
Name EssOptions_14: "A3000001100130001011001101020_01 00"
Name EssOptions_15: "A3000001100130001011001101020_01 00"
Name EssOptions_16: "A3000001100130001011001101020_01 00"
Name EssOptions_18: "A3000001100130001011001101020_01 00"
Name EssOptions_2: "A1100000010121000011001111120_01000"
Name EssOptions_20: "A3100000000110001011011111020_01000"
Name EssOptions_25: "A3100000000130000000011100020_01000"
Name EssOptions_26: "A3100000000110001011011111020_01000"

Sheet Datos
A1: 1. Presupuesto | E1: 2. Fabricación real
A2: Datos del producto | E2: Datos del producto
A3: EST a salida de sal (%) | B3: 0.55 | E3: EST a salida de sal (%) | F3: 0.4999
A4: MG a saida de sal (%) | B4: 0.28 | E4: MG a saida de sal (%) | F4: 0.2599
A5: Datos de materia prima | E5: Datos de la fabricación
A6: Composición leche (g/L) | C6: FEGA(m/m) | E6: Fabricación, KG | F6: 10.71
A7: Materia grasa | B7: =C7*B12*1000 -> 38.887209 | C7: 0.0376 | E7: Litros leche puestos en fab (cuba) | F7: 85
A8: Proteinas totales | B8: =C8*B12*1000 -> 33.716037 | C8: 0.0326 | E8: KMG puestos en fabricacion (cuba) | F8: 3.026
A9: Lactosa | B9: 48 | C9: =C7/C8 -> 1.1533742 | E9: KMP puestos en fabricacion (cuba) | F9: 2.763
A10: Sales minerales y otros | B10: 9 | E10: KMG Nata suero recuperada puesta en fab | F10: 0
A11: Agua | B11: =B12*1000-SUM(B7:B10) -> 904.63103
A12: Densidad | B12: =(-0.2307*10^(-2)*C12^2-0.2655*C12+1040.51-C7*(-0.478*10^(-4)*C12^2+0.969*10^(-2)*C12+0.967))/1000 -> 1.0342343 | C12: 20 | D12: ⁰C | E12: Coste de la leche en fabrica | F12: euros/L
A13: Composición nata suero (g/L) | E13: Precio pagado al ganadero | F13: 0.362
A14: MG | B14: =C14/100*B27*1000 -> 423.62953 | C14: 43 | D14: % | E14: Coste transporte + otros recogida | F14: 0.021
A15: MP | B15: 5.91 | E15: Total euros/L | F15: =SUM(F13:F14) -> 0.383
A16: Precio materia (euros/kg) | E16: Materia grasa | F16: =B17*B7/1000 -> 0.1915
A17: MG | B17: =F15/B7*C17*1000 -> 4.9244985 | C17: 0.5 | E17: Materia proteica | F17: =B18*B8/1000 -> 0.1915
A18: MP | B18: =F15/B8*C18*1000 -> 5.6797897 | C18: =1-C17 -> 0.5
A19: Datos estándar
A20: Receta en volumen (debe sumar 100%)
A21: Leche (%) | B21: 1
A22: Nata de suero de recuperación (%) | B22: 0
A23: Coeficientes de recuperación
A24: Coef de recuperación MG
A25: Coef de recuperación MP | B25: 0.9465
A26: Otros datos
A27: Densidad nata (kg/L) | B27: =(-0.2307*10^(-2)*C12^2-0.2655*C12+1040.51-C14*(-0.478*10^(-4)*C12^2+0.969*10^(-2)*C12+0.967))/1000 -> 0.98518496

Sheet Estandar Tecnico
A1: ESTANDAR TECNICO | B1: Prod 1
A2: Análisis salida sal
A3: EST % | B3: =Datos!B3 -> 0.55
A4: MG | B4: =Datos!B4 -> 0.28
A5: G/ES % | B5: =B4/B3 -> 0.50909091
A6: HFD | B6: =(1-B3)/(1-B3*B5) -> 0.625
A7: ESM | B7: =B3-B4 -> 0.27
A9: MP en cuba (g/L) | B9: =B45 -> 33.716037
A10: Ratio recuperación MP (Rendimiento MP %) | B10: =Datos!B25 -> 0.9465
A11: Ratio recuperación MG (%) | B11: =B14/B17 -> 0.85102955
A12: Coef G (ESM queso obtenido a partir de MP leche) | B12: =B10*B9 -> 31.912229
A13: Litraje unitario | B13: =B7*1000/B12 -> 8.4607063
A14: MG teórica en la cuba (g/L) | B14: =B4*1000/B13 -> 33.094164
A15: MG Pérddias brutas suero (g/L) | B15: =B17-B14 -> 5.7930449
A16: MG Pérddias brutas suero (%) | B16: =B15/B17 -> 0.14897045
A17: MG estándar en la mezcla (g/L) | B17: =B42 -> 38.887209
A18: Consumo MG total leche en cuba | B18: =B17*B13 -> 329.01325
A19: Consumo MP total leche en cuba | B19: =B9*B13 -> 285.26149
A20: MG suero en cuba (g/L) | B20: =+B50/B13 -> 0
A21: MG Pérddas suero neta (g/L) | B21: =B15-B20 -> 5.7930449
A22: MG Pérddas suero neta (%) | B22: =+B21/B17 -> 0.14897045
A23: MG STD sin nata de suero (g/L) | B23: =+B17-B20 -> 38.887209
A24: Consumo MG (sólo MG comprada) (g/K queso) | B24: =B$23*B$13 -> 329.01325
A25: Consumo MP (sólo MP comprada) (g/K queso) | B25: =B$9*B$13 -> 285.26149
A26: Receta
A27: % Leche Oveja | B27: =Datos!B21 -> 1
A28: % Nata de Suero | B28: =Datos!B22 -> 0
B29: =SUM(B27:B28) -> 1
B30: =B32/B34 -> 1.1533742
A31: Composición leche
A32: MG Leche (g/L) | B32: =Datos!B7 -> 38.887209
A33: MG Nata de Suero (g/L) | B33: =Datos!B14 -> 423.62953
A34: MP Leche (g/L) | B34: =Datos!B8 -> 33.716037
A35: MP Nata de suero (g/L) | B35: =Datos!B15 -> 5.91
A36: Densidad Leche | B36: =Datos!B12/1000 -> 0.0010342343
A37: Densidad Nata de suero | B37: =Datos!B27 -> 0.98518496
B38: =SUMPRODUCT(B36:B37,B27:B28) -> 0.0010342343
A39: Leche en cubas
A40: MG Leche (g/L) | B40: =(B32*B27) -> 38.887209
A41: MG Nata de suero (g/L) | B41: =(B33*B28) -> 0
...

Sheet Desviaciones
A1: Análisis de desviaciones | B1: Estándar | C1: Real
A2: Fabricación, KG | C2: 100
A3: EST | B3: ='Estandar Tecnico'!B3 -> 0.55 | C3: =Datos!F3 -> 0.4999
A4: MG | B4: ='Estandar Tecnico'!B4 -> 0.28 | C4: =Datos!F4 -> 0.2599
A5: ESM | B5: =B3-B4 -> 0.27 | C5: =C3-C4 -> 0.24
A6: HFD | B6: =(1-B3)/(1-B4) -> 0.625 | C6: =(1-C3)/(1-C4) -> 0.6757195
A7: G/ES | B7: =B4/B3 -> 0.50909091 | C7: =C4/C3 -> 0.51990398
A8: Litros leche puestos en fab (cuba) | B8: =B12/B15*1000 -> 846.07063 | C8: =Datos!F7 -> 85
A9: Composición leche en cuba MG (g/L) | B9: ='Estandar Tecnico'!B17 -> 38.887209 | C9: =C11/C8*1000 -> 35.6
A10: Composición leche en cuba MP (g/L) | B10: ='Estandar Tecnico'!B9 -> 33.716037 | C10: =C12/C8*1000 -> 32.505882
A11: KMG puestos en fabricacion (cuba) | B11: =B$4/B$19*C$2 -> 28.931597 | C11: =Datos!F8 -> 3.026
A12: KMP puestos en fabricacion (cuba) | B12: =C$2*B$5/B$20 -> 28.526149 | C12: =Datos!F9 -> 2.763
A13: KMG Nata suero recuperada puesta en fab | B13: =B8*B26/1000 -> 0 | C13: =Datos!F10 -> 0
A14: factor MG/MP leche cubas | B14: =B11/B12 -> 1.0142132 | C14: =C11/C12 -> 1.0951864
A15: g MP/L leche en cuba | B15: ='Estandar Tecnico'!B9 -> 33.716037 | C15: =C31*C2/C8 -> 32.505882
A16: g MG/L leche en cuba | B16: ='Estandar Tecnico'!B17 -> 38.887209 | C16: =C30*C2/C8 -> 35.6
A17: MG teórica en cuba g/L | B17: =B21/B18 -> 33.094164 | C17: =C21/C18 -> 305.76471
A18: Litraje unitario (L/Kg) | B18: =(B5*1000/B15)/B20 -> 8.4607063 | C18: =(C5*1000/C15)/C20 -> 0.85
A19: Recup MG | B19: 0.9678 | C19: =(C4*C2)/C11 -> 8.5888962
A20: Recup MP | B20: ='Estandar Tecnico'!B10 -> 0.9465 | C20: =C5*C2/C12 -> 8.6862106
A21: gr MG queso/kg queso | B21: =B4*1000 -> 280 | C21: =C4*1000 -> 259.9
A22: g ESM queso/kg queso | B22: =B5*1000 -> 270 | C22: =C5*1000 -> 240
A23: factor MG/MP queso | B23: =B21/B22 -> 1.037037 | C23: =C21/C22 -> 1.0829167
A24: MG pérdida bruta (g/L) | B24: =B16-B17 -> 5.7930449 | C24: =C16-C17 -> -270.16471
A25: MG pérdida bruta % | B25: =B24/B16 -> 0.14897045 | C25: =C24/C16 -> -7.5888962
A26: MG suero recuperada puesta en fab g/L | B26: ='Estandar Tecnico'!B20 -> 0 | C26: =C13*1000/C8 -> 0
A27: MG pérdida neta g/L | B27: =B24-B26 -> 5.7930449 | C27: =C24-C26 -> -270.16471
A28: MG pérdida neta % | B28: =B27/B16 -> 0.14897045 | C28: =C27/C16 -> -7.5888962
F29: Con MG total y abono nata suero
A30: Consumo técnico MG/kg queso (total cuba) | B30: =B11/C2*1000 -> 289.31597 | C30: =C11/C2*1000 -> 30.26 | D30: =(B11-C11)*B32 -> 127.57208 | F30: Std | G30: Real | H30: Dif | I30: Valor
A31: Consumo técnico MP/kg queso | B31: =B12/C2*1000 -> 285.26149 | C31: =C12/C2*1000 -> 27.63 | D31: =(B12-C12)*B33 -> 146.32927 | E31: MG leche cuba | F31: =B11 -> 28.931597 | G31: =C11 -> 3.026 | H31: =F31-G31 -> 25.905597 | I31: =H31*B38 -> 127.57208
A32: Coste medio mezcla en cuba MG (ponderado con NS = 0) | B32: =(B11-B13)*B38/B11 -> 4.9244985 | C32: =(C11-C13)*C38/C11 -> 4.9244985 | D32: =(B32-C32)*C11 -> 0 | E32: MG nata suero | F32: =-B13 -> 0 | G32: =-C13 -> 0 | H32: =F32-G32 -> 0 | I32: =H32*B38 -> 0
A33: Coste medio mezcla en cuba MP | B33: ='Estandar Tecnico'!B54 -> 5.6797897 | C33: ='Estandar Tecnico'!B54 -> 5.6797897 | D33: =(B33-C33)*C31*C2/1000 -> 0 | E33: MP leche cuba | F33: =B12 -> 28.526149 | G33: =C12 -> 2.763 | H33: =F33-G33 -> 25.763149 | I33: =H33*B39 -> 146.32927
D34: =SUM(D30:D33) -> 273.90134 | I34: =SUM(I31:I33) -> 273.90134
F35: Con MG sin nata de suero
A36: Consumo MG/kg queso (sin nata suero) | B36: =(B11-B13)/C2*1000 -> 289.31597 | C36: =(C11-C13)/C2*1000 -> 30.26 | D36: =((B36-C36)*B38*C2/1000) -> 127.57208 | F36: Std | G36: Real | H36: Dif | I36: Valor
A37: Consumo MP/kg queso | B37: =B12/C2*1000 -> 285.26149 | C37: =C12/C2*1000 -> 27.63 | D37: =((B37-C37)*B39*C2/1000) -> 146.32927 | E37: MG leche compra | F37: =(B11-B13) -> 28.931597 | G37: =C11-C13 -> 3.026 | H37: =F37-G37 -> 25.905597 | I37: =H37*B38 -> 127.57208
A38: Coste medio mezcla en cuba MG (coste compra MG) | B38: ='Estandar Tecnico'!B53 -> 4.9244985 | C38: ='Estandar Tecnico'!B53 -> 4.9244985 | D38: =(B38-C38)*C36*C2/1000 -> 0 | E38: MP leche compra | F38: =B12 -> 28.526149 | G38: =C12 -> 2.763 | H38: =F38-G38 -> 25.763149 | I38: =H38*B39 -> 146.32927
A39: Coste medio mezcla en cuba MP | B39: ='Estandar Tecnico'!B54 -> 5.6797897 | C39: ='Estandar Tecnico'!B54 -> 5.6797897 | D39: =(B39-C39)*C37*C2/1000 -> 0 | I39: =SUM(I37:I38) -> 273.90134
D40: =SUM(D36:D39) -> 273.90134
...

Sheet Proceso
A1: Descomposición del proceso de fabricación de queso y coproductos obtenidos
A4: Componente | B4: leche (kg) | C4: leche (% m/m) | D4: leche (% m/v) | E4: queso salida de sal (kg) | F4: queso salida de sal (% m/m) | G4: suero entero (kg) | H4: suero entero (% m/m) | I4: Nata de suero obtenida (kg) | J4: Nata de suero obtenida (% m/m) | K4: suero desnatado (kg) | L4: suero desnatado (% m/m) | M4: suero polvo (kg) | N4: suero polvo (% m/m) | O4: queso curado (kg) | P4: queso curado (% m/m)
A5: Agua | B5: =B18*B19-SUM(B6:B9) -> 90.463103 | C5: =B5/SUM($B$5:$B$9) -> 0.87468676 | E5: =B$21*(1-B22) -> 5.3187049 | F5: =E5/SUM($E$5:$E$9) -> 0.45 | G5: =B5-E5 -> 85.144398 | H5: =G5/SUM($G$5:$G$9) -> 0.92948256 | I5: =I10-SUM(I6:I9) -> 0.7062341 | J5: =1-SUM(J6:J9) -> 0.58752139 | K5: =G5-I5 -> 84.438164 | L5: =K5/SUM($K$5:$K$9) -> 0.93402955 | M5: =K5*(1-H19) -> 0.25331449 | N5: =M5/SUM($M$5:$M$9) -> 0.040744294 | O5: =O10-SUM(O6:O9) -> 3.9003836 | P5: =O5/$O$10 -> 0.375
A6: Materia grasa | B6: =Datos!B7/1000*B$18 -> 3.8887209 | C6: =B6/SUM($B$5:$B$9) -> 0.0376 | D6: =B6/1000 -> 0.0038887209 | E6: =B$21*B23 -> 3.3094164 | F6: =E6/SUM($E$5:$E$9) -> 0.28 | G6: =B6-E6 -> 0.57930449 | H6: =G6/SUM($G$5:$G$9) -> 0.006324003 | I6: =G6*B33 -> 0.48082273 | J6: =B32 -> 0.4 | K6: =G6-I6 -> 0.098481764 | L6: =K6/SUM($K$5:$K$9) -> 0.0010893756 | M6: =K6 -> 0.098481764 | N6: =M6/SUM($M$5:$M$9) -> 0.01584027 | O6: =E6 -> 3.3094164 | P6: =O6/$O$10 -> 0.31818182
A7: Proteinas totales | B7: =Datos!B8/1000*B$18 -> 3.3716037 | C7: =B7/SUM($B$5:$B$9) -> 0.0326 | D7: =B7/1000 -> 0.0033716037 | E7: =(B21*B26)-SUM(E8:E9) -> 2.8579174 | F7: =E7/SUM($E$5:$E$9) -> 0.2418 | G7: =B7-E7 -> 0.51368631 | H7: =G7/SUM($G$5:$G$9) -> 0.0056076791 | I7: 0.005 | J7: =I7/I10 -> 0.0041595371 | K7: =G7-I7 -> 0.50868631 | L7: =K7/SUM($K$5:$K$9) -> 0.0056269348 | M7: =K7 -> 0.50868631 | N7: =M7/SUM($M$5:$M$9) -> 0.081819498 | O7: =E7 -> 2.8579174 | P7: =O7/$O$10 -> 0.27477273
A8: Lactosa | B8: =Datos!B9/1000*B$18 -> 4.8 | C8: =B8/SUM($B$5:$B$9) -> 0.046411148 | D8: =B8/1000 -> 0.0048 | E8: =B29*B21 -> 0.15128761 | F8: =E8/SUM($E$5:$E$9) -> 0.0128 | G8: =B8-E8 -> 4.6487124 | H8: =G8/SUM($G$5:$G$9) -> 0.050747873 | I8: 0.005 | J8: =I8/I10 -> 0.0041595371 | K8: =G8-I8 -> 4.6437124 | L8: =K8/SUM($K$5:$K$9) -> 0.051367349 | M8: =K8 -> 4.6437124 | N8: =M8/SUM($M$5:$M$9) -> 0.74691654 | O8: =E8 -> 0.15128761 | P8: =O8/$O$10 -> 0.014545455
A9: Sales minerales y otros | B9: =Datos!B10/1000*B$18 -> 0.9 | C9: =B9/SUM($B$5:$B$9) -> 0.0087020903 | D9: =B9/1000 -> 0.0009 | E9: =B30*B21 -> 0.1820179 | F9: =E9/SUM($E$5:$E$9) -> 0.0154 | G9: =B9-E9 -> 0.7179821 | H9: =G9/SUM($G$5:$G$9) -> 0.0078378832 | I9: 0.005 | J9: =I9/I10 -> 0.0041595371 | K9: =G9-I9 -> 0.7129821 | L9: =K9/SUM($K$5:$K$9) -> 0.0078867933 | M9: =K9 -> 0.7129821 | N9: =M9/SUM($M$5:$M$9) -> 0.11467939 | O9: =E9 -> 0.1820179 | P9: =O9/$O$10 -> 0.0175
A10: Peso total (kg) | B10: =SUM(B5:B9) -> 103.42343 | C10: =SUM(C5:C9) -> 1 | E10: =SUM(E5:E9) -> 11.819344 | F10: =SUM(F5:F9) -> 1 | G10: =B10-E10 -> 91.604083 | H10: =SUM(H5:H9) -> 1 | I10: =I6/J6 -> 1.2020568 | J10: =SUM(J5:J9) -> 1 | K10: =G10-I10 -> 90.402026 | L10: =SUM(L5:L9) -> 1 | M10: =SUM(M5:M9) -> 6.2171771 | N10: =SUM(N5:N9) -> 1 | O10: =E10*(1-H20) -> 10.401023 | P10: =SUM(P5:P9) -> 1
A12: EST | C12: =SUM(C6:C9) -> 0.12531324 | D12: =SUM(D6:D9) -> 0.012960325 | F12: =1-F5 -> 0.55 | H12: =1-H5 -> 0.070517438 | J12: =1-J5 -> 0.41247861 | L12: =1-L5 -> 0.065970452 | N12: =1-N5 -> 0.95925571 | P12: =1-P5 -> 0.625
A13: G/ES | F13: =F6/F12 -> 0.50909091 | H13: =H6/H12 -> 0.089679987 | J13: =J6/J12 -> 0.96974725 | L13: =L6/L12 -> 0.016513084 | N13: =N6/N12 -> 0.016513084 | P13: =P6/P12 -> 0.50909091
A14: ESM | C14: =SUM(C7:C9) -> 0.087713238 | F14: =SUM(F7:F9) -> 0.27 | H14: =SUM(H7:H9) -> 0.064193435 | J14: =SUM(J7:J9) -> 0.012478611 | L14: =SUM(L7:L9) -> 0.064881077 | N14: =SUM(N7:N9) -> 0.94341544 | P14: =SUM(P7:P9) -> 0.30681818
A15: HFD | F15: =F5/(1-F6) -> 0.625 | H15: =H5/(1-H6) -> 0.93539802 | J15: =J5/(1-J6) -> 0.97920231 | L15: =L5/(1-L6) -> 0.93504817 | N15: =N5/(1-N6) -> 0.041400083 | P15: =P5/(1-P6) -> 0.55
A17: Cálculos del std técnico
A18: Volumen (L) | B18: 100 | E18: % suero obtenido | H18: =G10/B10 -> 0.88571889
A19: Densidad (g/L) | B19: =Datos!B12 -> 1.0342343 | E19: % agua eliminada secado suero | H19: 0.997
A20: L/kg (obtenidos del coef de recup de ESM) | B20: ='Estandar Tecnico'!B13 -> 8.4607063 | E20: merma maduración | H20: 0.12
A21: Kg con vol std | B21: =B18/B20 -> 11.819344
A22: EST | B22: ='Estandar Tecnico'!B3 -> 0.55 | E22: Recup ESM | F22: =SUM(E7:E9)/B7 -> 0.9465 | H22: =SUM(E7:E9)/F22 -> 3.3716037
A23: MG | B23: ='Estandar Tecnico'!B4 -> 0.28 | E23: Recup MG | F23: =E6/B6 -> 0.85102955 | H23: =E6/F23 -> 3.8887209
A24: G/ES | B24: =B23/B22 -> 0.50909091 | E24: L/kg | F24: =B18/E10 -> 8.4607063
A25: HFD | B25: =(1-B22)/(1-B22*B24) -> 0.625
A26: ESM | B26: =B22-B23 -> 0.27 | E26: Kg ESM | F26: =SUM(E7:E9) -> 3.1912229
E27: Kg MG | F27: =E6 -> 3.3094164
A28: Queso a salida de sal | F28: =SUM(F26:F27) -> 6.5006393
A29: Lactosa (% m/m) | B29: 0.0128 | F29: =F28/E10 -> 0.55
A30: Sales minerales (% m/m) | B30: 0.0154 | F30: =F28/F29 -> 11.819344
A32: Composición en MG nata obtenida en desnatado | B32: 0.4
A33: Eficiencia del desnatado en MG | B33: 0.83

Sheet densidad
A1: Ejemplo para cálculo de la densidad en función de la MG y la Tª
A2: Fuente: | B2: La masse volumique du lait et de crèmes de 65°C à l40°C (archives-ouvertes.fr)
A4: Temperatura | B4: 20 | C4: 20 | D4: 20 | E4: 15 | F4: 15 | G4: 15 | H4: 25 | I4: 25 | J4: 25
A5: Mat grasa (% m/m) | B5: 3.75 | C5: 43 | D5: 1 | E5: 3.75 | F5: 43 | G5: 1 | H5: 3.75 | I5: 43 | J5: 1
A7: densidad | B7: =-0.2307*10^(-2)*B4^2-0.2655*B4+1040.51-B5*(-0.478*10^(-4)*B4^2+0.969*10^(-2)*B4+0.967) -> 1029.9959 | C7: =-0.2307*10^(-2)*C4^2-0.2655*C4+1040.51-C5*(-0.478*10^(-4)*C4^2+0.969*10^(-2)*C4+0.967) -> 985.18496 | D7: =-0.2307*10^(-2)*D4^2-0.2655*D4+1040.51-D5*(-0.478*10^(-4)*D4^2+0.969*10^(-2)*D4+0.967) -> 1033.1355 | E7: =-0.2307*10^(-2)*E4^2-0.2655*E4+1040.51-E5*(-0.478*10^(-4)*E4^2+0.969*10^(-2)*E4+0.967) -> 1031.8774 | F7: =-0.2307*10^(-2)*F4^2-0.2655*F4+1040.51-F5*(-0.478*10^(-4)*F4^2+0.969*10^(-2)*F4+0.967) -> 988.63984 | G7: =-0.2307*10^(-2)*G4^2-0.2655*G4+1040.51-G5*(-0.478*10^(-4)*G4^2+0.969*10^(-2)*G4+0.967) -> 1034.9068 | H7: =-0.2307*10^(-2)*H4^2-0.2655*H4+1040.51-H5*(-0.478*10^(-4)*H4^2+0.969*10^(-2)*H4+0.967) -> 1028.008 | I7: =-0.2307*10^(-2)*I4^2-0.2655*I4+1040.51-I5*(-0.478*10^(-4)*I4^2+0.969*10^(-2)*I4+0.967) -> 981.7175 | J7: =-0.2307*10^(-2)*J4^2-0.2655*J4+1040.51-J5*(-0.478*10^(-4)*J4^2+0.969*10^(-2)*J4+0.967) -> 1031.2513
