Workbook
Name _100_PV: #REF!
Name _100_SVI: #REF!
Name _1000_XM: #REF!
Name _145110: #REF!
Name _162460: [4]STEPHAN!$B$2:$P$71
Name _170_LIGHT: #REF!
Name _170_PV: #REF!
Name _171015: #REF!
Name _171064: #REF!
Name _171066: #REF!
Name _171068: #REF!
Name _171510: #REF!
Name _171562: #REF!
Name _172012: #REF!
Name _172020: #REF!
Name _172022: #REF!
Name _172062: #REF!
Name _172510: [4]STEPHAN!$B$2:$Q$71
Name _172610: [4]STEPHAN!$B$2:$Q$71
Name _176072: #REF!
Name A_impresión_IM: #REF!
Name bd: #REF!
Name bof: "ComboBox1"
Name dd: #REF!
Name EssLatest: "JAN"
Name EssLatest_10: "JAN"
Name EssLatest_11: "JAN"
Name EssLatest_12: "JAN"
Name EssLatest_13: "JAN"
Name EssLatest_14: "JAN"
Name EssLatest_15: "JAN"
Name EssLatest_16: "JAN"
Name EssLatest_18: "JAN"
Name EssLatest_2: "JANN0"
Name EssLatest_20: "YTDMM01"
Name EssLatest_25: "YTDMM01"
Name EssLatest_26: "YTDMM01"
Name EssLatest_3: "JANN0"
Name EssLatest_38: "JAN"
Name EssLatest_39: "JAN"
Name EssLatest_4: "JANN0"
Name EssLatest_47: "JAN"
Name EssLatest_48: "JAN"
Name EssLatest_5: "JANN0"
Name EssLatest_6: "YTDMM01"
Name EssLatest_7: "YTDMM01"
Name EssLatest_8: "YTDMM01"
Name EssLatest_9: "JAN"
Name EssOptions_10: "A3000001100130001011001101020_01 00"
Name EssOptions_11: "A3000001100130001011001101020_01 00"
Name EssOptions_12: "A3000001100130001011001101020_01 00"
Name EssOptions_13: "A3000001100130001011001101020_01 00"
Name EssOptions_14: "A3000001100130001011001101020_01 00"
Name EssOptions_15: "A3000001100130001011001101020_01 00"
Name EssOptions_16: "A3000001100130001011001101020_01 00"
Name EssOptions_18: "A3000001100130001011001101020_01 00"
Name EssOptions_2: "A1100000010121000011001111120_01000"
Name EssOptions_20: "A3100000000110001011011111020_01000"
Name EssOptions_25: "A3100000000130000000011100020_01000"
Name EssOptions_26: "A3100000000110001011011111020_01000"

Sheet Std con datos de csv fab_queso
A1: 1. Presupuesto | B1: Mezcla | C1: Vaca | D1: Oveja | E1: Bajo en MG
A2: Datos del producto
A3: EST a salida de sal (%) | B3: 0.5495 | C3: 0.5563 | D3: 0.5635 | E3: 0.5047
A4: MG a saida de sal (%) | B4: 0.3028 | C4: 0.3005 | D4: 0.3093 | E4: 0.2022
A5: Coste de la leche en fabrica
A6: Precio pagado al ganadero (euros/L) | B6: 0.494 | C6: 0.494 | D6: 1.375 | E6: 0.494
A7: Coste transporte + otros recogida (euros/L) | B7: 0.021 | C7: 0.021 | D7: 0.021 | E7: 0.021
A8: Total euros/L | B8: =SUM(B6:B7) -> 0.515 | C8: =SUM(C6:C7) -> 0.515 | D8: =SUM(D6:D7) -> 1.396 | E8: =SUM(E6:E7) -> 0.515
A10: Reparto precio MG leche | B10: 0.5 | C10: 0.5 | D10: 0.5 | E10: 0.5
A11: Reparto precio MP leche (1 - MG) | B11: =1-B10 -> 0.5 | C11: =1-C10 -> 0.5 | D11: =1-D10 -> 0.5 | E11: =1-E10 -> 0.5
A12: Valor MG leche en fábrica (euros/L) | B12: =B38*B19/1000 -> 0.2575 | C12: =C38*C19/1000 -> 0.2575 | D12: =D38*D19/1000 -> 0.698 | E12: =E38*E19/1000 -> 0.2575
A13: Valor MP leche en fábrica (euros/L) | B13: =B39*B20/1000 -> 0.2575 | C13: =C39*C20/1000 -> 0.2575 | D13: =D39*D20/1000 -> 0.698 | E13: =E39*E20/1000 -> 0.2575
A14: Datos de materia prima
A15: Composición leche
A16: Materia grasa (% m/m) | B16: 0.04 | C16: 0.0376 | D16: 0.0687 | E16: 0.024
A17: Proteinas totales (% m/m) | B17: 0.030993046 | C17: 0.03072033 | D17: 0.055090424 | E17: 0.032548054
A18: Factor MG/MP | B18: =B16/B17 -> 1.2906121 | C18: =C16/C17 -> 1.2239452 | D18: =D16/D17 -> 1.2470407 | E18: =E16/E17 -> 0.73737128
A19: Materia grasa (g/L) | B19: =B16*B25 -> 41.369261 | C19: =C16*C25 -> 38.887209 | D19: =D16*D25 -> 71.049455 | E19: =E16*E25 -> 24.821995
A20: Proteinas totales (g/L) | B20: =B17*B25 -> 32.053986 | C20: =C17*C25 -> 31.772018 | D20: =D17*D25 -> 56.974449 | E20: =E17*E25 -> 33.662818
A21: Lactosa | B21: 48 | C21: 48 | D21: 48 | E21: 48
A22: Sales minerales y otros | B22: 9 | C22: 9 | D22: 9 | E22: 9
A23: Agua | B23: =B25-SUM(B19:B22) -> 903.80829 | C23: =C25-SUM(C19:C22) -> 906.57505 | D23: =D25-SUM(D19:D22) -> 849.17486 | E23: =E25-SUM(E19:E22) -> 918.76499
A24: Temperatura a la que se hace la medida (⁰C) | B24: 20 | C24: 20 | D24: 20 | E24: 20
A25: Densidad | B25: =-0.2307*10^(-2)*B24^2-0.2655*B24+1040.51-B16*(-0.478*10^(-4)*B24^2+0.969*10^(-2)*B24+0.967) -> 1034.2315 | C25: =-0.2307*10^(-2)*C24^2-0.2655*C24+1040.51-C16*(-0.478*10^(-4)*C24^2+0.969*10^(-2)*C24+0.967) -> 1034.2343 | D25: =-0.2307*10^(-2)*D24^2-0.2655*D24+1040.51-D16*(-0.478*10^(-4)*D24^2+0.969*10^(-2)*D24+0.967) -> 1034.1988 | E25: =-0.2307*10^(-2)*E24^2-0.2655*E24+1040.51-E16*(-0.478*10^(-4)*E24^2+0.969*10^(-2)*E24+0.967) -> 1034.2498
A26: Composición suero entero (g/L)
A27: EST | B27: 6.5 | C27: 6.5 | D27: 6.5 | E27: 6.5
A28: MG | B28: 4 | C28: 4 | D28: 4 | E28: 4
A29: MP | B29: 8 | C29: 8 | D29: 8 | E29: 8
A30: Lactosa | B30: 48 | C30: 48 | D30: 48 | E30: 48
A31: Sales minerales y otros
A32: Densidad | B32: 1.03 | C32: 1.03 | D32: 1.03 | E32: 1.03
A33: Composición nata suero (g/L)
A34: Materia grasa (% m/m) | B34: 0.43 | C34: 0.43 | D34: 0.43 | E34: 0.43
A35: MG | B35: =B34*B48*1000 -> 423.62953 | C35: =C34*C48*1000 -> 423.62953 | D35: =D34*D48*1000 -> 423.62953 | E35: =E34*E48*1000 -> 423.62953
A36: MP | B36: 5.91 | C36: 5.91 | D36: 5.91 | E36: 5.91
A37: Precio materia (euros/kg)
A38: MG | B38: =B8/B19*B10*1000 -> 6.2244283 | C38: =C8/C19*C10*1000 -> 6.6217147 | D38: =D8/D19*D10*1000 -> 9.8241429 | E38: =E8/E19*E10*1000 -> 10.373864
A39: MP | B39: =B8/B20*B11*1000 -> 8.0333224 | C39: =C8/C20*C11*1000 -> 8.1046159 | D39: =D8/D20*D11*1000 -> 12.251106 | E39: =E8/E20*E11*1000 -> 7.6493893
A40: Datos estándar
A41: Receta en volumen (debe sumar 100%)
...

Sheet Std con datos de csv fab_qu (2)
B1: Ejemplo
A2: Datos del producto
A3: EST a salida de sal (%) | B3: 0.55
A4: MG a saida de sal (%) | B4: 0.28
A5: Datos de materia prima
A6: Composición leche
A7: Materia grasa (% m/m) | B7: 0.0334
A8: Proteinas totales (% m/m) | B8: 0.0311
A9: Factor MG/MP | B9: =B7/B8 -> 1.073955
A10: Materia grasa (g/L) | B10: =B7*B16 -> 34.543585
A11: Proteinas totales (g/L) | B11: =B8*B16 -> 32.164835
A12: Lactosa | B12: 48
A13: Sales minerales y otros | B13: 9
A14: Agua | B14: =B16-SUM(B10:B13) -> 910.53065
A15: Temperatura a la que se hace la medida (⁰C) | B15: 20
A16: Densidad | B16: =-0.2307*10^(-2)*B15^2-0.2655*B15+1040.51-B7*(-0.478*10^(-4)*B15^2+0.969*10^(-2)*B15+0.967) -> 1034.2391
A17: Composición suero entero (g/L)
A18: EST | B18: 6.5
A19: MG | B19: 4
A20: MP | B20: 8
A21: Lactosa | B21: 48
A22: Sales minerales y otros
A23: Densidad | B23: 1.03
A24: Composición nata suero (g/L)
A25: Materia grasa (% m/m) | B25: 0.43
A26: MG | B26: =B25*B36*1000 -> 423.62953
A27: MP | B27: 5.91
A28: Datos estándar
A29: Receta en volumen (debe sumar 100%)
A30: Leche (%) | B30: 1
A31: Nata de suero de recuperación (%) | B31: =1-B30 -> 0
A32: Coeficientes de recuperación
A33: Coef de recuperación MG
A34: Coef de recuperación MP | B34: 0.9465
A35: Otros datos
A36: Densidad nata (kg/L) | B36: =(-0.2307*10^(-2)*B15^2-0.2655*B15+1040.51-B25*100*(-0.478*10^(-4)*B15^2+0.969*10^(-2)*B15+0.967))/1000 -> 0.98518496
A38: 2. Estándar técnico del producto
A39: Análisis salida sal
A40: EST % | B40: ='Std con datos de csv fab_qu (2)'!B3 -> 0.55
A41: MG | B41: ='Std con datos de csv fab_qu (2)'!B4 -> 0.28
...
