Workbook
Name _100_PV: #REF!
Name _100_SVI: #REF!
Name _1000_XM: #REF!
Name _145110: #REF!
Name _162460: [4]STEPHAN!$B$2:$P$71
Name _170_LIGHT: #REF!
Name _170_PV: #REF!
Name _171015: #REF!
Name _171064: #REF!
Name _171066: #REF!
Name _171068: #REF!
Name _171510: #REF!
Name _171562: #REF!
Name _172012: #REF!
Name _172020: #REF!
Name _172022: #REF!
Name _172062: #REF!
Name _172510: [4]STEPHAN!$B$2:$Q$71
Name _172610: [4]STEPHAN!$B$2:$Q$71
Name _176072: #REF!
Name A_impresión_IM: #REF!
Name bd: #REF!
Name bof: "ComboBox1"
Name dd: #REF!
Name EssLatest: "JAN"
Name EssLatest_10: "JAN"
Name EssLatest_11: "JAN"
Name EssLatest_12: "JAN"
Name EssLatest_13: "JAN"
Name EssLatest_14: "JAN"
Name EssLatest_15: "JAN"
Name EssLatest_16: "JAN"
Name EssLatest_18: "JAN"
Name EssLatest_2: "JANN0"
Name EssLatest_20: "YTDMM01"
Name EssLatest_25: "YTDMM01"
Name EssLatest_26: "YTDMM01"
Name EssLatest_3: "JANN0"
Name EssLatest_38: "JAN"
Name EssLatest_39: "JAN"
Name EssLatest_4: "JANN0"
Name EssLatest_47: "JAN"
Name EssLatest_48: "JAN"
Name EssLatest_5: "JANN0"
Name EssLatest_6: "YTDMM01"
Name EssLatest_7: "YTDMM01"
Name EssLatest_8: "YTDMM01"
Name EssLatest_9: "JAN"
Name EssOptions_10: "A3000001100130001011001101020_01 00"
Name EssOptions_11: "A3000001100130001011001101020_01 00"
Name EssOptions_12: "A3000001100130001011001101020_01 00"
Name EssOptions_13: "A3000001100130001011001101020_01 00"
Name EssOptions_14: "A3000001100130001011001101020_01 00"
Name EssOptions_15: "A3000001100130001011001101020_01 00"
Name EssOptions_16: "A3000001100130001011001101020_01 00"
Name EssOptions_18: "A3000001100130001011001101020_01 00"
Name EssOptions_2: "A1100000010121000011001111120_01000"
Name EssOptions_20: "A3100000000110001011011111020_01000"
Name EssOptions_25: "A3100000000130000000011100020_01000"
Name EssOptions_26: "A3100000000110001011011111020_01000"

Sheet Liquidación leche
A1: Ejemplo simplificado de liquidación mensual de precio de leche de vaca
A3: 1. Datos presupuesto
A4: Parámetro para pago por calidad (valores presupuestados) | B4: Resultado analítico | C4: Límite prima | D4: Prima (€/L) | E4: Calidad real | F4: Bonificación (€/L)
A5: Grasa (MG) | B5: 0.041 | C5: MG > 3,80% | D5: + 0,005 | E5: 3 décimas (4,10 vs 3,80) | F5: 0.015
A6: Proteína (MP) | B6: 0.0345 | C6: MP > 3,30% | D6: + 0,008 | E6: 1,5 décimas (3,45 vs 3,30) | F6: 0.012
A7: Recuento de células somáticas (RCS) | B7: 180000 | C7: RCS < 200.000 | D7: + 0,007 | F7: 0.007
A8: Recuento de bacterias totales (RB) | B8: 20000 | C8: RB < 50.000 | D8: + 0,008 | F8: 0.008
A9: Bienestar animal | B9: Sí | D9: + 0,010 | E9: certificacion Welfair/AENOR | F9: 0.01
A10: Letra Q | B10: Sí | D10: + 0,005 | F10: 0.005
A12: Concepto | B12: Precio pagado
A13: Precio base | B13: 0.51
A14: Primas Calidad (MG + MP) | B14: =SUM(F5:F6) -> 0.027
A15: Higiene (RCS + RB) | B15: =SUM(F7:F8) -> 0.015
A16: Sostenibilidad (BA + Letra Q) | B16: =SUM(F9:F10) -> 0.015
A17: Precio neto final | B17: =SUM(B13:B16) -> 0.567
A19: 2. Liquidación real mensual
A20: Parámetro para pago por calidad Mes de ABRIL | B20: Resultado analítico | C20: Límite prima | D20: Prima | E20: Calidad real (diferencia entre resultado y límite prima) | F20: Bonificación (€/L)
A21: Grasa (MG) | B21: 0.0395 | C21: 0.038 | D21: 0.005 | E21: =(B21-C21)*1000 -> 1.5 | F21: =D21*E21 -> 0.0075
A22: Proteína (MP) | B22: 0.034 | C22: 0.033 | D22: 0.008 | E22: =(B22-C22)*1000 -> 1 | F22: =D22*E22 -> 0.008
A23: Recuento de células somáticas (RCS) | B23: 195000 | C23: 200000 | D23: 0.007 | E23: =IF(B23<C23,"Aplica","No aplica") -> Aplica | F23: =IF(B23<C23,D23,0) -> 0.007
A24: Recuento de bacterias totales (RB) | B24: 52000 | C24: 50000 | D24: 0.008 | E24: =IF(B24<C24,"Aplica","No aplica") -> No aplica | F24: =IF(B24<C24,D24,0) -> 0
A25: Bienestar animal | B25: Sí | D25: 0.01 | F25: =IF(B25="Sí",D25,0) -> 0.01
A26: Letra Q | B26: Sí | D26: 0.005 | F26: =IF(B26="Sí",D26,0) -> 0.005
A28: Concepto | B28: Precio pagado
A29: Precio base | B29: 0.51
A30: Primas Calidad (MG + MP) | B30: =SUM(F21:F22) -> 0.0155
A31: Higiene (RCS + RB) | B31: =SUM(F23:F24) -> 0.007
A32: Sostenibilidad (BA + Letra Q) | B32: =SUM(F25:F26) -> 0.015
A33: Precio neto final | B33: =SUM(B29:B32) -> 0.5475

Sheet Datos materia prima
A1: Datos de materia prima
A2: Coste de la leche en fabrica | B2: Presupuesto | C2: Real
A3: 1. Precio base | B3: 0.51 | C3: 0.51
A4: 2. Primas calidad (MG/MP) | B4: 0.027 | C4: 0.0155
A5: 3. Primas higiene | B5: 0.015 | C5: 0.007
A6: 4. Prima sostenibilidad | B6: 0.015 | C6: 0.015
A7: 5. Total precio al ganadero | B7: =SUM(B3:B6) -> 0.567 | C7: =SUM(C3:C6) -> 0.5475
A8: 6. Coste transporte + otros recogida | B8: 0.021 | C8: 0.025
A9: Total euros/L | B9: =SUM(B7:B8) -> 0.588 | C9: =SUM(C7:C8) -> 0.5725
A10: 7. Materia grasa | B10: =B27*B16/1000 -> 0.2352 | C10: =C27*C16/1000 -> 0.229
A11: 8. Proteína | B11: =B28*B17/1000 -> 0.3528 | C11: =C28*C17/1000 -> 0.3435
A12: Composición leche (% m/m)
A13: 9. Materia grasa | B13: 0.041 | C13: 0.0395
A14: 10. Proteinas totales | B14: 0.0345 | C14: 0.034
A15: Composición leche (g/L)
A16: 11. Materia grasa | B16: =B13*B21*1000 -> 42.403446 | C16: =C13*C21*1000 -> 40.852168
A17: 12. Proteinas totales | B17: =B14*B21*1000 -> 35.680948 | C17: =C14*C21*1000 -> 35.163892
A18: 13. Lactosa | B18: 48 | C18: 48
A19: 14. Sales minerales y otros | B19: 9 | C19: 9
A20: 15. Agua | B20: =B21*1000-SUM(B16:B19) -> 899.146 | C20: =C21*1000-SUM(C16:C19) -> 901.21604
A21: 16. Densidad | B21: =(-0.2307*10^(-2)*B22^2-0.2655*B22+1040.51-B13*(-0.478*10^(-4)*B22^2+0.969*10^(-2)*B22+0.967))/1000 -> 1.0342304 | C21: =(-0.2307*10^(-2)*C22^2-0.2655*C22+1040.51-C13*(-0.478*10^(-4)*C22^2+0.969*10^(-2)*C22+0.967))/1000 -> 1.0342321
A22: ⁰C medida | B22: 20 | C22: 20
A23: Valoración materia prima
A24: 17. Valoración MG | B24: 0.4 | C24: 0.4
A25: 18. Valoración MP | B25: =1-B24 -> 0.6 | C25: =1-C24 -> 0.6
A26: Precio resultante de la materia
A27: 19. Precio MG (euros/kg) | B27: =B9/B16*B24*1000 -> 5.546719 | C27: =C9/C16*C24*1000 -> 5.6055776
A28: 20. Precio MP (euros/kg) | B28: =B9/B17*B25*1000 -> 9.8876295 | C28: =C9/C17*C25*1000 -> 9.7685434

Sheet Estándar técnico
A1: Estándar de producto | B1: Fórmulas | C1: Vaca | D1: Mezcla | E1: Oveja | F1: Bajo en MG | G1: Mozza
A2: Fabricación, KG | C2: 1 | D2: 1 | E2: 1 | F2: 1 | G2: 1
A3: 1. Características del queso
A4: EST salida salado | C4: 0.55 | D4: 0.5495 | E4: 0.5635 | F4: 0.5047 | G4: 0.4
A5: MG salida salado | C5: 0.28 | D5: 0.3028 | E5: 0.3093 | F5: 0.2022 | G5: 0.18
A6: ESM | B6: =B4-B5 | C6: =C4-C5 -> 0.27 | D6: =D4-D5 -> 0.2467 | E6: =E4-E5 -> 0.2542 | F6: =F4-F5 -> 0.3025 | G6: =G4-G5 -> 0.22
A7: HFD | B7: =(1-B4)/(1-B5) | C7: =(1-C4)/(1-C5) -> 0.625 | D7: =(1-D4)/(1-D5) -> 0.64615605 | E7: =(1-E4)/(1-E5) -> 0.63196757 | F7: =(1-F4)/(1-F5) -> 0.62083229 | G7: =(1-G4)/(1-G5) -> 0.73170732
A8: G/ES | B8: =B5/B4 | C8: =C5/C4 -> 0.50909091 | D8: =D5/D4 -> 0.55104641 | E8: =E5/E4 -> 0.54889086 | F8: =F5/F4 -> 0.40063404 | G8: =G5/G4 -> 0.45
A9: 2. Composición de la leche de fabricación
A10: Leche en cuba MG (g/L) | C10: 40.58 | D10: 41.37 | E10: 71.05 | F10: 24.82 | G10: 38.1
A11: Leche en cuba MP (g/L) | C11: 34.05 | D11: 32.05 | E11: 56.97 | F11: 33.66 | G11: 32.1
A12: 3. Datos tecnológicos
A13: Recup MP (dato real de la fabricación) | C13: 0.9465 | D13: 0.9678 | E13: 0.9348 | F13: 0.9733 | G13: 0.9446
A14: 4. Cálculos
A15: ESM queso obtenido a partir de MP leche (g/L) | B15: =B13*B11 | C15: =C13*C11 -> 32.228325 | D15: =D13*D11 -> 31.01799 | E15: =E13*E11 -> 53.255556 | F15: =F13*F11 -> 32.761278 | G15: =G13*G11 -> 30.32166
A16: Litraje unitario | B16: =B6*1000/B15 | C16: =C6*1000/C15 -> 8.3777236 | D16: =D6*1000/D15 -> 7.953449 | E16: =E6*1000/E15 -> 4.7732109 | F16: =F6*1000/F15 -> 9.2334615 | G16: =G6*1000/G15 -> 7.2555394
A17: MG teórica en la cuba (g/L) | B17: =B5*1000/B16 | C17: =C5*1000/C16 -> 33.421967 | D17: =D5*1000/D16 -> 38.071534 | E17: =E5*1000/E16 -> 64.799148 | F17: =F5*1000/F16 -> 21.898613 | G17: =G5*1000/G16 -> 24.808631
A18: Recup MG | B18: =B17/B10 | C18: =C17/C10 -> 0.82360687 | D18: =D17/D10 -> 0.92026913 | E18: =E17/E10 -> 0.91202179 | F18: =F17/F10 -> 0.88229706 | G18: =G17/G10 -> 0.65114517
A19: MG pérdida bruta en suero (g/L) | B19: =B17-B10 | C19: =C17-C10 -> -7.1580333 | D19: =D17-D10 -> -3.2984663 | E19: =E17-E10 -> -6.2508518 | F19: =F17-F10 -> -2.9213871 | G19: =G17-G10 -> -13.291369
A20: MG pérdida bruta en suero % | B20: =B19/B10 | C20: =C19/C10 -> -0.17639313 | D20: =D19/D10 -> -0.079730874 | E20: =E19/E10 -> -0.08797821 | F20: =F19/F10 -> -0.11770294 | G20: =G19/G10 -> -0.34885483
A21: Consumo MG/kg queso | B21: =B10*B16 | C21: =C10*C16 -> 339.96803 | D21: =D10*D16 -> 329.03418 | E21: =E10*E16 -> 339.13663 | F21: =F10*F16 -> 229.17452 | G21: =G10*G16 -> 276.43605
A22: Consumo MP/kg queso | B22: =B11*B16 | C22: =C11*C16 -> 285.26149 | D22: =D11*D16 -> 254.90804 | E22: =E11*E16 -> 271.92982 | F22: =F11*F16 -> 310.79832 | G22: =G11*G16 -> 232.90282

Sheet Datos fabricación
A1: Fabricación
A2: Datos de la fabricación real
A3: Fabricación, KG | B3: 10.71
A4: EST a salida de sal (%) | B4: 0.532
A5: MG a salida de sal (%) | B5: 0.276
A6: Litros leche puestos en fab (cuba) | B6: 90
A7: Composición leche MG (g/L) | B7: ='Datos materia prima'!C16 -> 40.852168
A8: Composición leche MP (g/L) | B8: ='Datos materia prima'!C17 -> 35.163892
A9: KMG puestos en fabricacion (cuba) | B9: =B7*B6/1000 -> 3.6766951
A10: KMP puestos en fabricacion (cuba) | B10: =B8*B6/1000 -> 3.1647502
A11: Utilización de nata de suero
A12: KMG Nata suero recuperada puesta en fab | B12: 0
A13: MG (% m/m) | B13: 0.4
A14: MG (g/L) | B14: =B13/100*B16*1000*100 -> 394
A15: MP (g/L) | B15: 5.91
A16: Densidad nata a 20 °C (kg/L) | B16: 0.985

Sheet Desviaciones
A1: Análisis de desviaciones | B1: Estándar | C1: Real
A2: Fabricación, KG | C2: ='Datos fabricación'!B3 -> 10.71
A3: EST | B3: ='Estándar técnico'!C4 -> 0.55 | C3: ='Datos fabricación'!B4 -> 0.532
A4: MG | B4: ='Estándar técnico'!C5 -> 0.28 | C4: ='Datos fabricación'!B5 -> 0.276
A5: ESM | B5: =B3-B4 -> 0.27 | C5: =C3-C4 -> 0.256
A6: HFD | B6: =(1-B3)/(1-B4) -> 0.625 | C6: =(1-C3)/(1-C4) -> 0.64640884
A7: G/ES | B7: =B4/B3 -> 0.50909091 | C7: =C4/C3 -> 0.51879699
A8: gr MG queso/kg queso | B8: =B4*1000 -> 280 | C8: =C4*1000 -> 276
A9: g ESM queso/kg queso | B9: =B5*1000 -> 270 | C9: =C5*1000 -> 256
A10: factor MG/MP queso | B10: =B8/B9 -> 1.037037 | C10: =C8/C9 -> 1.078125
A11: Litros leche puestos en fab (cuba) | B11: =B15/B19*1000 -> 89.72542 | C11: ='Datos fabricación'!B6 -> 90
A12: Composición leche en cuba MG (g/L) | B12: ='Estándar técnico'!C10 -> 40.58 | C12: =C14/C11*1000 -> 40.852168
A13: Composición leche en cuba MP (g/L) | B13: ='Estándar técnico'!C11 -> 34.05 | C13: =C15/C11*1000 -> 35.163892
A14: KMG puestos en fabricacion (cuba) | B14: =B$4/B$22*C$2 -> 3.6410575 | C14: ='Datos fabricación'!B9 -> 3.6766951
A15: KMP puestos en fabricacion (cuba) | B15: =C$2*B$5/B$23 -> 3.0551506 | C15: ='Datos fabricación'!B10 -> 3.1647502
A16: KMG Nata suero recuperada puesta en fab | B16: =B11*B26/1000 -> 0 | C16: ='Datos fabricación'!B12 -> 0
A17: factor MG/MP leche cubas | B17: =B14/B15 -> 1.1917768 | C17: =C14/C15 -> 1.1617647
A18: g MG/L leche en cuba | B18: =B12 -> 40.58 | C18: =C31*C2/C11 -> 40.852168
A19: g MP/L leche en cuba | B19: =B13 -> 34.05 | C19: =C32*C2/C11 -> 35.163892
A20: MG teórica en cuba g/L | B20: =B8/B21 -> 33.421967 | C20: =C8/C21 -> 32.844
A21: Litraje unitario (L/Kg) | B21: =(B5*1000/B19)/B23 -> 8.3777236 | C21: =(C5*1000/C19)/C23 -> 8.4033613
A22: Recup MG | B22: ='Estándar técnico'!C18 -> 0.82360687 | C22: =(C4*C2)/C14 -> 0.80397202
A23: Recup MP | B23: ='Estándar técnico'!C13 -> 0.9465 | C23: =C5*C2/C15 -> 0.86634325
A24: MG pérdida bruta (g/L) | B24: =B18-B20 -> 7.1580333 | C24: =C18-C20 -> 8.0081681
A25: MG pérdida bruta % | B25: =B24/B18 -> 0.17639313 | C25: =C24/C18 -> 0.19602798
A26: MG suero recuperada puesta en fab g/L | B26: 0 | C26: =C16*1000/C11 -> 0
A27: MG pérdida neta g/L | B27: =B24-B26 -> 7.1580333 | C27: =C24-C26 -> 8.0081681
A28: MG pérdida neta % | B28: =B27/B18 -> 0.17639313 | C28: =C27/C18 -> 0.19602798
A30: Consumos y desviaciones por consumo y precio | B30: Std | C30: Real | D30: Desv kg | E30: Desv total € | F30: Desv € /kg
A31: Consumo g MG/kg queso | B31: =B14/C2*1000 -> 339.96803 | C31: =C14/C2*1000 -> 343.29553 | D31: =(B31-C31)*C2/1000 -> -0.03563758 | E31: =D31*B34 -> -0.19767164 | F31: =E31/C2 -> -0.018456736
A32: Consumo g MP/kg queso | B32: =B15/C2*1000 -> 285.26149 | C32: =C15/C2*1000 -> 295.49489 | D32: =(B32-C32)*C2/1000 -> -0.10959968 | E32: =D32*B35 -> -1.0836811 | F32: =E32/C2 -> -0.10118404
A33: Total desviaciones por consumo | E33: =SUM(E31:E32) -> -1.2813527 | F33: =SUM(F31:F32) -> -0.11964078
A34: Coste MG (euros/kg) | B34: ='Datos materia prima'!B27 -> 5.546719 | C34: ='Datos materia prima'!C27 -> 5.6055776 | E34: =(B34-C34)*C2 -> -0.63037598 | F34: =E34/C2 -> -0.058858635
A35: Coste MP (euros/kg) | B35: ='Datos materia prima'!B28 -> 9.8876295 | C35: ='Datos materia prima'!C28 -> 9.7685434 | E35: =(B35-C35)*C2 -> 1.2754126 | F35: =E35/C2 -> 0.11908614
A36: Total desviaciones por precio | E36: =SUM(E34:E35) -> 0.64503662 | F36: =E36/C2 -> 0.060227509
A38: Desviaciones por componente de materia prima | B38: Std | C38: Real | D38: Dif | E38: Desv total € | F38: Desv € /kg
A39: MG leche cuba | B39: =B14 -> 3.6410575 | C39: =C14 -> 3.6766951 | D39: =B39-C39 -> -0.03563758 | E39: =D39*B34 -> -0.19767164 | F39: =E39/C2 -> -0.018456736
A40: MP leche cuba | B40: =B15 -> 3.0551506 | C40: =C15 -> 3.1647502 | D40: =B40-C40 -> -0.10959968 | E40: =D40*B35 -> -1.0836811 | F40: =E40/C2 -> -0.10118404
E41: =SUM(E39:E40) -> -1.2813527 | F41: =SUM(F39:F40) -> -0.11964078
A43: Desviaciones por composición queso + tecnología | B43: Std | C43: Real | D43: Desv kg | E43: Desv total € | F43: Desv € /kg
...

Sheet Proceso
A1: Descomposición del proceso de fabricación de queso y coproductos obtenidos
A4: Componente | B4: leche (kg) | C4: leche (% m/m) | D4: leche (% m/v) | E4: queso salida de sal (kg) | F4: queso salida de sal (% m/m) | G4: suero entero (kg) | H4: suero entero (% m/m) | I4: Nata de suero obtenida (kg) | J4: Nata de suero obtenida (% m/m) | K4: suero desnatado (kg) | L4: suero desnatado (% m/m) | M4: suero polvo (kg) | N4: suero polvo (% m/m) | O4: queso curado (kg) | P4: queso curado (% m/m)
A5: Agua | B5: =B18*B19-SUM(B6:B9) -> 89.9146 | C5: =B5/SUM($B$5:$B$9) -> 0.86938655 | E5: =B$21*(1-B22) -> 5.3713875 | F5: =E5/SUM($E$5:$E$9) -> 0.45 | G5: =B5-E5 -> 84.543212 | H5: =G5/SUM($G$5:$G$9) -> 0.92410464 | I5: =I10-SUM(I6:I9) -> 1.1031942 | J5: =1-SUM(J6:J9) -> 0.59195131 | K5: =G5-I5 -> 83.440018 | L5: =K5/SUM($K$5:$K$9) -> 0.93101157 | M5: =K5*(1-H19) -> 0.25032005 | N5: =M5/SUM($M$5:$M$9) -> 0.038910251 | O5: =O10-SUM(O6:O9) -> 3.9390175 | P5: =O5/$O$10 -> 0.375
A6: Materia grasa | B6: ='Datos materia prima'!B16/1000*B$18 -> 4.2403446 | C6: =B6/SUM($B$5:$B$9) -> 0.041 | D6: =B6/1000 -> 0.0042403446 | E6: =B$21*B23 -> 3.3421967 | F6: =E6/SUM($E$5:$E$9) -> 0.28 | G6: =B6-E6 -> 0.89814794 | H6: =G6/SUM($G$5:$G$9) -> 0.0098172598 | I6: =G6*B33 -> 0.74546279 | J6: =B32 -> 0.4 | K6: =G6-I6 -> 0.15268515 | L6: =K6/SUM($K$5:$K$9) -> 0.0017036387 | M6: =K6 -> 0.15268515 | N6: =M6/SUM($M$5:$M$9) -> 0.023733686 | O6: =E6 -> 3.3421967 | P6: =O6/$O$10 -> 0.31818182
A7: Proteinas totales | B7: ='Datos materia prima'!B17/1000*B$18 -> 3.5680948 | C7: =B7/SUM($B$5:$B$9) -> 0.0345 | D7: =B7/1000 -> 0.0035680948 | E7: =(B21*B26)-SUM(E8:E9) -> 2.8862255 | F7: =E7/SUM($E$5:$E$9) -> 0.2418 | G7: =B7-E7 -> 0.6818693 | H7: =G7/SUM($G$5:$G$9) -> 0.0074532132 | I7: 0.005 | J7: =I7/I10 -> 0.0026828972 | K7: =G7-I7 -> 0.6768693 | L7: =K7/SUM($K$5:$K$9) -> 0.0075524091 | M7: =K7 -> 0.6768693 | N7: =M7/SUM($M$5:$M$9) -> 0.10521392 | O7: =E7 -> 2.8862255 | P7: =O7/$O$10 -> 0.27477273
A8: Lactosa | B8: ='Datos materia prima'!B18/1000*B$18 -> 4.8 | C8: =B8/SUM($B$5:$B$9) -> 0.046411322 | D8: =B8/1000 -> 0.0048 | E8: =B29*B21 -> 0.15278613 | F8: =E8/SUM($E$5:$E$9) -> 0.0128 | G8: =B8-E8 -> 4.6472139 | H8: =G8/SUM($G$5:$G$9) -> 0.050796649 | I8: 0.005 | J8: =I8/I10 -> 0.0026828972 | K8: =G8-I8 -> 4.6422139 | L8: =K8/SUM($K$5:$K$9) -> 0.051797146 | M8: =K8 -> 4.6422139 | N8: =M8/SUM($M$5:$M$9) -> 0.72159503 | O8: =E8 -> 0.15278613 | P8: =O8/$O$10 -> 0.014545455
A9: Sales minerales y otros | B9: ='Datos materia prima'!B19/1000*B$18 -> 0.9 | C9: =B9/SUM($B$5:$B$9) -> 0.0087021229 | D9: =B9/1000 -> 0.0009 | E9: =B30*B21 -> 0.18382082 | F9: =E9/SUM($E$5:$E$9) -> 0.0154 | G9: =B9-E9 -> 0.71617918 | H9: =G9/SUM($G$5:$G$9) -> 0.0078282394 | I9: 0.005 | J9: =I9/I10 -> 0.0026828972 | K9: =G9-I9 -> 0.71117918 | L9: =K9/SUM($K$5:$K$9) -> 0.0079352338 | M9: =K9 -> 0.71117918 | N9: =M9/SUM($M$5:$M$9) -> 0.11054712 | O9: =E9 -> 0.18382082 | P9: =O9/$O$10 -> 0.0175
A10: Peso total (kg) | B10: =SUM(B5:B9) -> 103.42304 | C10: =SUM(C5:C9) -> 1 | E10: =SUM(E5:E9) -> 11.936417 | F10: =SUM(F5:F9) -> 1 | G10: =B10-E10 -> 91.486622 | H10: =SUM(H5:H9) -> 1 | I10: =I6/J6 -> 1.863657 | J10: =SUM(J5:J9) -> 1 | K10: =G10-I10 -> 89.622965 | L10: =SUM(L5:L9) -> 1 | M10: =SUM(M5:M9) -> 6.4332676 | N10: =SUM(N5:N9) -> 1 | O10: =E10*(1-H20) -> 10.504047 | P10: =SUM(P5:P9) -> 1
A12: EST | C12: =SUM(C6:C9) -> 0.13061345 | D12: =SUM(D6:D9) -> 0.013508439 | F12: =1-F5 -> 0.55 | H12: =1-H5 -> 0.075895362 | J12: =1-J5 -> 0.40804869 | L12: =1-L5 -> 0.068988428 | N12: =1-N5 -> 0.96108975 | P12: =1-P5 -> 0.625
A13: G/ES | F13: =F6/F12 -> 0.50909091 | H13: =H6/H12 -> 0.12935257 | J13: =J6/J12 -> 0.98027517 | L13: =L6/L12 -> 0.024694557 | N13: =N6/N12 -> 0.024694557 | P13: =P6/P12 -> 0.50909091
A14: ESM | C14: =SUM(C7:C9) -> 0.089613445 | F14: =SUM(F7:F9) -> 0.27 | H14: =SUM(H7:H9) -> 0.066078102 | J14: =SUM(J7:J9) -> 0.0080486915 | L14: =SUM(L7:L9) -> 0.067284789 | N14: =SUM(N7:N9) -> 0.93735606 | P14: =SUM(P7:P9) -> 0.30681818
A15: HFD | F15: =F5/(1-F6) -> 0.625 | H15: =H5/(1-H6) -> 0.93326676 | J15: =J5/(1-J6) -> 0.98658551 | L15: =L5/(1-L6) -> 0.93260039 | N15: =N5/(1-N6) -> 0.039856185 | P15: =P5/(1-P6) -> 0.55
A17: Cálculos del std técnico
A18: Volumen (L) | B18: 100 | E18: % suero obtenido | H18: =G10/B10 -> 0.88458648
A19: Densidad (g/L) | B19: ='Datos materia prima'!B21 -> 1.0342304 | E19: % agua eliminada secado suero | H19: 0.997
A20: L/kg (obtenidos del coef de recup de ESM) | B20: ='Estándar técnico'!C16 -> 8.3777236 | E20: merma maduración | H20: 0.12
A21: Kg con vol std | B21: =B18/B20 -> 11.936417
A22: EST | B22: ='Estándar técnico'!C4 -> 0.55 | E22: Recup ESM | F22: =SUM(E7:E9)/B7 -> 0.90323622 | H22: =SUM(E7:E9)/F22 -> 3.5680948
A23: MG | B23: ='Estándar técnico'!C5 -> 0.28 | E23: Recup MG | F23: =E6/B6 -> 0.78818987 | H23: =E6/F23 -> 4.2403446
A24: G/ES | B24: =B23/B22 -> 0.50909091 | E24: L/kg | F24: =B18/E10 -> 8.3777236
A25: HFD | B25: =(1-B22)/(1-B22*B24) -> 0.625
A26: ESM | B26: =B22-B23 -> 0.27 | E26: Kg ESM | F26: =SUM(E7:E9) -> 3.2228325
E27: Kg MG | F27: =E6 -> 3.3421967
A28: Queso a salida de sal | F28: =SUM(F26:F27) -> 6.5650292
A29: Lactosa (% m/m) | B29: 0.0128 | F29: =F28/E10 -> 0.55
A30: Sales minerales (% m/m) | B30: 0.0154 | F30: =F28/F29 -> 11.936417
A32: Composición en MG nata obtenida en desnatado | B32: 0.4
A33: Eficiencia del desnatado en MG | B33: 0.83

Sheet densidad
A1: Ejemplo para cálculo de la densidad en función de la MG y la Tª
A2: Fuente: | B2: La masse volumique du lait et de crèmes de 65°C à l40°C (archives-ouvertes.fr)
A4: Temperatura | B4: 20 | C4: 20 | D4: 20 | E4: 15 | F4: 15 | G4: 15 | H4: 25 | I4: 25 | J4: 25
A5: Mat grasa (% m/m) | B5: 3.75 | C5: 43 | D5: 1 | E5: 3.75 | F5: 43 | G5: 1 | H5: 3.75 | I5: 43 | J5: 1
A7: densidad | B7: =-0.2307*10^(-2)*B4^2-0.2655*B4+1040.51-B5*(-0.478*10^(-4)*B4^2+0.969*10^(-2)*B4+0.967) -> 1029.9959 | C7: =-0.2307*10^(-2)*C4^2-0.2655*C4+1040.51-C5*(-0.478*10^(-4)*C4^2+0.969*10^(-2)*C4+0.967) -> 985.18496 | D7: =-0.2307*10^(-2)*D4^2-0.2655*D4+1040.51-D5*(-0.478*10^(-4)*D4^2+0.969*10^(-2)*D4+0.967) -> 1033.1355 | E7: =-0.2307*10^(-2)*E4^2-0.2655*E4+1040.51-E5*(-0.478*10^(-4)*E4^2+0.969*10^(-2)*E4+0.967) -> 1031.8774 | F7: =-0.2307*10^(-2)*F4^2-0.2655*F4+1040.51-F5*(-0.478*10^(-4)*F4^2+0.969*10^(-2)*F4+0.967) -> 988.63984 | G7: =-0.2307*10^(-2)*G4^2-0.2655*G4+1040.51-G5*(-0.478*10^(-4)*G4^2+0.969*10^(-2)*G4+0.967) -> 1034.9068 | H7: =-0.2307*10^(-2)*H4^2-0.2655*H4+1040.51-H5*(-0.478*10^(-4)*H4^2+0.969*10^(-2)*H4+0.967) -> 1028.008 | I7: =-0.2307*10^(-2)*I4^2-0.2655*I4+1040.51-I5*(-0.478*10^(-4)*I4^2+0.969*10^(-2)*I4+0.967) -> 981.7175 | J7: =-0.2307*10^(-2)*J4^2-0.2655*J4+1040.51-J5*(-0.478*10^(-4)*J4^2+0.969*10^(-2)*J4+0.967) -> 1031.2513
